<!-- 阮一峰JS教程阅读札记之JS错误处理篇 -->

# 错误处理

在写 JS 的过程中，经常会遇到控制台报错，这期我们就来探索一下 JS 里的错误类型和机制。

JavaScript解析或执行时，`一旦发生错误，引擎就会抛出一个错误对象`。然后整个程序就中断在发生错误的地方，不再往下执行。

JavaScript原生提供一个`Error`构造函数，所有抛出的错误都是这个构造函数的实例。

Error对象的实例必须有`message属性，表示出错时的提示信息`，其他属性则没有提及。大多数JavaScript引擎，对Error实例`还提供name和stack属性，分别表示错误的名称和错误的堆栈`，但它们是非标准的，不是每种实现都有。

  message：错误提示信息
  name：错误名称（非标准属性）
  stack：错误的堆栈（非标准属性）

```js
if (error.name) {
  console.log(error.name + ': ' + error.message);
}

// stack属性用来查看错误发生时的堆栈。
function throwit() {
  throw new Error('');
}

function catchit() {
  try {
    throwit();
  } catch(e) {
    console.log(e.stack); // print stack trace
  }
}

catchit()
// Error
//    at throwit (~/examples/throwcatch.js:9:11)
//    at catchit (~/examples/throwcatch.js:3:9)
//    at repl:1:5
```

## 错误类型(Error的6个派生对象)

### SyntaxError

`SyntaxError`是 `解析代码时发生的语法错误`。

```js
// 变量名错误
var 1a;

// 缺少括号
console.log 'hello');
```

### ReferenceError

`ReferenceError`是`引用一个不存在的变量时发生的错误`。

```js
unknownVariable
// ReferenceError: unknownVariable is not defined

// 另一种触发场景是，`将一个值分配给无法分配的对象`，比如对函数的运行结果或者this赋值。

console.log() = 1
// ReferenceError: Invalid left-hand side in assignment

this = 1
// ReferenceError: Invalid left-hand side in assignment
```

上面代码对函数console.log的运行结果和this赋值，结果都引发了ReferenceError错误。

### RangeError

RangeError是当`一个值超出有效范围时发生的错误`。主要有几种情况，一是数组长度为负数，二是Number对象的方法参数超出范围，以及函数堆栈超过最大值。

```js
new Array(-1)
// RangeError: Invalid array length

(1234).toExponential(21)
// RangeError: toExponential() argument must be between 0 and 20
```

### TypeError

TypeError是`变量或参数不是预期类型时发生的错误`。比如，对字符串、布尔值、数值等原始类型的值使用new命令，就会抛出这种错误，因为new命令的参数应该是一个构造函数。

```js
new 123
//TypeError: number is not a func

var obj = {};
obj.unknownMethod()
// TypeError: obj.unknownMethod is not a function
```

上面代码的第二种情况，调用对象不存在的方法，会抛出TypeError错误。

### URIError

URIError是`URI相关函数的参数不正确时抛出的错误`，主要涉及`encodeURI()`、`decodeURI()`、`encodeURIComponent()`、`decodeURIComponent()`、`escape()`和`unescape()`这六个函数。

```js
decodeURI('%2')
// URIError: URI malformed
```

### EvalError

eval函数`没有被正确执行时，会抛出EvalError错误`。该错误类型已经不再在ES5中出现了，只是为了保证与以前代码兼容，才继续保留。

以上这6种派生错误，连同原始的Error对象，都是构造函数。开发者可以使用它们，人为生成错误对象的实例。

### 总结

以上这6种派生错误，连同原始的Error对象，都是构造函数。开发者可以使用它们，手动生成错误对象的实例。这些构造函数都接受一个函数，代表错误提示信息（message）。

```js
var err1 = new Error('出错了！');
var err2 = new RangeError('出错了，变量超出有效范围！');
var err3 = new TypeError('出错了，变量类型无效！');

err1.message // "出错了！"
err2.message // "出错了，变量超出有效范围！"
err3.message // "出错了，变量类型无效！"
```

## 自定义错误

```js
function UserError(message) {
  this.message = message || '默认信息';
  this.name = 'UserError';
}

UserError.prototype = new Error();
UserError.prototype.constructor = UserError; // 继承

new UserError('自定义错误！')；
```

## throw 语句

throw可以接受各种值作为参数。JavaScript引擎一旦遇到throw语句，就会停止执行后面的语句，并将throw语句的参数值，返回给用户。

```js
// 抛出一个字符串
throw "Error！"; // Uncaught Error！

// 抛出一个数值
throw 42; // Uncaught 42

// 抛出一个布尔值
throw true; // Uncaught true

// 抛出一个对象
throw {toString: function() { return "Error!"; } // Uncaught {toString: ƒ}
```

如果只是简单的错误，返回一条出错信息就可以了，但是如果遇到复杂的情况，就需要在出错以后进一步处理。这时最好的做法是使用`throw语句手动抛出一个Error对象。`

```js
throw new Error('出错了!');

// 或者
function UserError(message) {
  this.message = message || "默认信息";
  this.name = "UserError";
}

UserError.prototype.toString = function() {
  return this.name + ': "' + this.message + '"';
}

throw new UserError("出错了！");

// 可以通过自定义一个assert函数，规范化throw抛出的信息。

function assert(expression, message) {
  if (!expression)
    throw {name: 'Assertion Exception', message: message};
}

assert(typeof myVar != 'undefined', 'myVar is undefined!');
```

## try…catch结构

对错误进行处理，需要使用`try...catch`结构。

```js
try {
  throw new Error('出错了!');
} catch (e) {
  console.log(e.name + ": " + e.message);
  console.log(e.stack);
}
// Error: 出错了!
//   at <anonymous>:3:9
//   ...
```

catch接受一个参数，表示try代码块抛出的值。

```js
function throwIt(exception) {
  try {
    throw exception;
  } catch (e) {
    console.log('Caught: ' + e);
  }
}

throwIt(3);
// Caught: 3
throwIt('hello');
// Caught: hello
throwIt(new Error('An error happened'));
// Caught: Error: An error happened
```

catch代码块捕获错误之后，`程序不会中断，会按照正常流程继续执行下去`。

catch代码块之中，还可以再抛出错误，甚至使用嵌套的try...catch结构。

```js
var n = 100;

try {
  throw n;
} catch (e) {
  if (e <= 50) {
    // ...
  } else {
    throw e;
  }
}
// Uncaught 100
```

为了捕捉不同类型的错误，catch代码块之中可以加入判断语句。

```js
try {
  foo.bar();
} catch (e) {
  if (e instanceof EvalError) {
    console.log(e.name + ": " + e.message);
  } else if (e instanceof RangeError) {
    console.log(e.name + ": " + e.message);
  }
  // ...
}
```

这种结构多多少少是对`结构化编程原则一种破坏`，处理不当就会变成类似goto语句的效果，`应该谨慎使用`。

## finally代码块

try...catch结构允许在最后添加一个finally代码块，表示`不管是否出现错误，都必需在最后运行的语句。`

即使有return语句在前，finally代码块依然会得到执行，且在其执行完毕后，才会显示return语句的值。

```js
function idle(x) {
  try {
    console.log(x);
    return 'result';
  } finally {
    console.log("FINALLY");
  }
}

idle('hello')
// hello
// FINALLY
// "result"
```

注意，return的执行是排在finally代码之前，只是等finally代码执行完毕后才返回。

```js
var count = 0;
function countUp() {
  try {
    return count;
  } finally {
    count++;
  }
}

countUp()
// 0
count
// 1
```

### 经典用法

```js
openFile();

try {
  writeFile(Data);
} catch(e) {
  handleError(e);
} finally {
  closeFile();
}
```

1. 首先打开一个文件，然后在try代码块中写入文件，如果没有发生错误，则运行finally代码块关闭文件；
2. 一旦发生错误，则先使用catch代码块处理错误，再使用finally代码块关闭文件。

### 调用顺序

```js
function f() {
  try {
    console.log(0);
    throw 'bug';
  } catch(e) {
    console.log(1);
    return true; // 重点：这句原本会延迟到finally代码块结束再执行
    console.log(2); // 不会运行
  } finally {
    console.log(3);
    return false; // 这句会覆盖掉前面那句return，因为是return，所以函数体直接返回false了，catch里的return没有被执行
    console.log(4); // 不会运行
  }

  console.log(5); // 不会运行
}

var result = f();
// 0
// 1
// 3

result
// false
```